2018-06-24 18:18:31,005 ERROR: Exception on /user/gdiaz [GET] [in /Users/gilberto.diaz/.local/share/virtualenvs/microblog-clBJ8VCo/lib/python3.6/site-packages/flask/app.py:1761]
Traceback (most recent call last):
  File "/Users/gilberto.diaz/.local/share/virtualenvs/microblog-clBJ8VCo/lib/python3.6/site-packages/flask/app.py", line 2292, in wsgi_app
    response = self.full_dispatch_request()
  File "/Users/gilberto.diaz/.local/share/virtualenvs/microblog-clBJ8VCo/lib/python3.6/site-packages/flask/app.py", line 1815, in full_dispatch_request
    rv = self.handle_user_exception(e)
  File "/Users/gilberto.diaz/.local/share/virtualenvs/microblog-clBJ8VCo/lib/python3.6/site-packages/flask/app.py", line 1718, in handle_user_exception
    reraise(exc_type, exc_value, tb)
  File "/Users/gilberto.diaz/.local/share/virtualenvs/microblog-clBJ8VCo/lib/python3.6/site-packages/flask/_compat.py", line 35, in reraise
    raise value
  File "/Users/gilberto.diaz/.local/share/virtualenvs/microblog-clBJ8VCo/lib/python3.6/site-packages/flask/app.py", line 1813, in full_dispatch_request
    rv = self.dispatch_request()
  File "/Users/gilberto.diaz/.local/share/virtualenvs/microblog-clBJ8VCo/lib/python3.6/site-packages/flask/app.py", line 1799, in dispatch_request
    return self.view_functions[rule.endpoint](**req.view_args)
  File "/Users/gilberto.diaz/.local/share/virtualenvs/microblog-clBJ8VCo/lib/python3.6/site-packages/flask_login/utils.py", line 261, in decorated_view
    return func(*args, **kwargs)
  File "/Users/gilberto.diaz/workspace/microblog/src/routes.py", line 90, in user
    return render_template('user.html', title=c_user.username, user=c_user, posts=posts)
  File "/Users/gilberto.diaz/.local/share/virtualenvs/microblog-clBJ8VCo/lib/python3.6/site-packages/flask/templating.py", line 135, in render_template
    context, ctx.app)
  File "/Users/gilberto.diaz/.local/share/virtualenvs/microblog-clBJ8VCo/lib/python3.6/site-packages/flask/templating.py", line 117, in _render
    rv = template.render(context)
  File "/Users/gilberto.diaz/.local/share/virtualenvs/microblog-clBJ8VCo/lib/python3.6/site-packages/jinja2/asyncsupport.py", line 76, in render
    return original_render(self, *args, **kwargs)
  File "/Users/gilberto.diaz/.local/share/virtualenvs/microblog-clBJ8VCo/lib/python3.6/site-packages/jinja2/environment.py", line 1008, in render
    return self.environment.handle_exception(exc_info, True)
  File "/Users/gilberto.diaz/.local/share/virtualenvs/microblog-clBJ8VCo/lib/python3.6/site-packages/jinja2/environment.py", line 780, in handle_exception
    reraise(exc_type, exc_value, tb)
  File "/Users/gilberto.diaz/.local/share/virtualenvs/microblog-clBJ8VCo/lib/python3.6/site-packages/jinja2/_compat.py", line 37, in reraise
    raise value.with_traceback(tb)
  File "/Users/gilberto.diaz/workspace/microblog/src/templates/user.html", line 1, in top-level template code
    {% extends 'base.html' %}
  File "/Users/gilberto.diaz/workspace/microblog/src/templates/base.html", line 33, in top-level template code
    {% block content %}{% endblock %}
  File "/Users/gilberto.diaz/workspace/microblog/src/templates/user.html", line 24, in block "content"
    <span class="badge badge-primary">Followers: {{ username.followers.count() }}</span>
  File "/Users/gilberto.diaz/.local/share/virtualenvs/microblog-clBJ8VCo/lib/python3.6/site-packages/jinja2/environment.py", line 430, in getattr
    return getattr(obj, attribute)
jinja2.exceptions.UndefinedError: 'username' is undefined
2018-06-24 18:18:48,164 ERROR: Exception on /user/gdiaz [GET] [in /Users/gilberto.diaz/.local/share/virtualenvs/microblog-clBJ8VCo/lib/python3.6/site-packages/flask/app.py:1761]
Traceback (most recent call last):
  File "/Users/gilberto.diaz/.local/share/virtualenvs/microblog-clBJ8VCo/lib/python3.6/site-packages/flask/app.py", line 2292, in wsgi_app
    response = self.full_dispatch_request()
  File "/Users/gilberto.diaz/.local/share/virtualenvs/microblog-clBJ8VCo/lib/python3.6/site-packages/flask/app.py", line 1815, in full_dispatch_request
    rv = self.handle_user_exception(e)
  File "/Users/gilberto.diaz/.local/share/virtualenvs/microblog-clBJ8VCo/lib/python3.6/site-packages/flask/app.py", line 1718, in handle_user_exception
    reraise(exc_type, exc_value, tb)
  File "/Users/gilberto.diaz/.local/share/virtualenvs/microblog-clBJ8VCo/lib/python3.6/site-packages/flask/_compat.py", line 35, in reraise
    raise value
  File "/Users/gilberto.diaz/.local/share/virtualenvs/microblog-clBJ8VCo/lib/python3.6/site-packages/flask/app.py", line 1813, in full_dispatch_request
    rv = self.dispatch_request()
  File "/Users/gilberto.diaz/.local/share/virtualenvs/microblog-clBJ8VCo/lib/python3.6/site-packages/flask/app.py", line 1799, in dispatch_request
    return self.view_functions[rule.endpoint](**req.view_args)
  File "/Users/gilberto.diaz/.local/share/virtualenvs/microblog-clBJ8VCo/lib/python3.6/site-packages/flask_login/utils.py", line 261, in decorated_view
    return func(*args, **kwargs)
  File "/Users/gilberto.diaz/workspace/microblog/src/routes.py", line 90, in user
    return render_template('user.html', title=c_user.username, user=c_user, posts=posts)
  File "/Users/gilberto.diaz/.local/share/virtualenvs/microblog-clBJ8VCo/lib/python3.6/site-packages/flask/templating.py", line 135, in render_template
    context, ctx.app)
  File "/Users/gilberto.diaz/.local/share/virtualenvs/microblog-clBJ8VCo/lib/python3.6/site-packages/flask/templating.py", line 117, in _render
    rv = template.render(context)
  File "/Users/gilberto.diaz/.local/share/virtualenvs/microblog-clBJ8VCo/lib/python3.6/site-packages/jinja2/asyncsupport.py", line 76, in render
    return original_render(self, *args, **kwargs)
  File "/Users/gilberto.diaz/.local/share/virtualenvs/microblog-clBJ8VCo/lib/python3.6/site-packages/jinja2/environment.py", line 1008, in render
    return self.environment.handle_exception(exc_info, True)
  File "/Users/gilberto.diaz/.local/share/virtualenvs/microblog-clBJ8VCo/lib/python3.6/site-packages/jinja2/environment.py", line 780, in handle_exception
    reraise(exc_type, exc_value, tb)
  File "/Users/gilberto.diaz/.local/share/virtualenvs/microblog-clBJ8VCo/lib/python3.6/site-packages/jinja2/_compat.py", line 37, in reraise
    raise value.with_traceback(tb)
  File "/Users/gilberto.diaz/workspace/microblog/src/templates/user.html", line 1, in top-level template code
    {% extends 'base.html' %}
  File "/Users/gilberto.diaz/workspace/microblog/src/templates/base.html", line 33, in top-level template code
    {% block content %}{% endblock %}
  File "/Users/gilberto.diaz/workspace/microblog/src/templates/user.html", line 24, in block "content"
    <span class="badge badge-primary">Followers: {{ username.followers.count() }}</span>
  File "/Users/gilberto.diaz/.local/share/virtualenvs/microblog-clBJ8VCo/lib/python3.6/site-packages/jinja2/environment.py", line 430, in getattr
    return getattr(obj, attribute)
jinja2.exceptions.UndefinedError: 'username' is undefined
