2018-06-24 12:25:49,650 INFO: Microblog startup [in /Users/gilberto.diaz/workspace/microblog/src/__init__.py:44]
2018-06-24 12:37:23,295 ERROR: Exception on /edit_profile [POST] [in /Users/gilberto.diaz/.local/share/virtualenvs/microblog-clBJ8VCo/lib/python3.6/site-packages/flask/app.py:1761]
Traceback (most recent call last):
  File "/Users/gilberto.diaz/.local/share/virtualenvs/microblog-clBJ8VCo/lib/python3.6/site-packages/sqlalchemy/engine/base.py", line 1193, in _execute_context
    context)
  File "/Users/gilberto.diaz/.local/share/virtualenvs/microblog-clBJ8VCo/lib/python3.6/site-packages/sqlalchemy/engine/default.py", line 508, in do_execute
    cursor.execute(statement, parameters)
sqlite3.IntegrityError: UNIQUE constraint failed: user.username

The above exception was the direct cause of the following exception:

Traceback (most recent call last):
  File "/Users/gilberto.diaz/.local/share/virtualenvs/microblog-clBJ8VCo/lib/python3.6/site-packages/flask/app.py", line 2292, in wsgi_app
    response = self.full_dispatch_request()
  File "/Users/gilberto.diaz/.local/share/virtualenvs/microblog-clBJ8VCo/lib/python3.6/site-packages/flask/app.py", line 1815, in full_dispatch_request
    rv = self.handle_user_exception(e)
  File "/Users/gilberto.diaz/.local/share/virtualenvs/microblog-clBJ8VCo/lib/python3.6/site-packages/flask/app.py", line 1718, in handle_user_exception
    reraise(exc_type, exc_value, tb)
  File "/Users/gilberto.diaz/.local/share/virtualenvs/microblog-clBJ8VCo/lib/python3.6/site-packages/flask/_compat.py", line 35, in reraise
    raise value
  File "/Users/gilberto.diaz/.local/share/virtualenvs/microblog-clBJ8VCo/lib/python3.6/site-packages/flask/app.py", line 1813, in full_dispatch_request
    rv = self.dispatch_request()
  File "/Users/gilberto.diaz/.local/share/virtualenvs/microblog-clBJ8VCo/lib/python3.6/site-packages/flask/app.py", line 1799, in dispatch_request
    return self.view_functions[rule.endpoint](**req.view_args)
  File "/Users/gilberto.diaz/.local/share/virtualenvs/microblog-clBJ8VCo/lib/python3.6/site-packages/flask_login/utils.py", line 261, in decorated_view
    return func(*args, **kwargs)
  File "/Users/gilberto.diaz/workspace/microblog/src/routes.py", line 101, in edit_profile
    db.session.commit()
  File "/Users/gilberto.diaz/.local/share/virtualenvs/microblog-clBJ8VCo/lib/python3.6/site-packages/sqlalchemy/orm/scoping.py", line 153, in do
    return getattr(self.registry(), name)(*args, **kwargs)
  File "/Users/gilberto.diaz/.local/share/virtualenvs/microblog-clBJ8VCo/lib/python3.6/site-packages/sqlalchemy/orm/session.py", line 943, in commit
    self.transaction.commit()
  File "/Users/gilberto.diaz/.local/share/virtualenvs/microblog-clBJ8VCo/lib/python3.6/site-packages/sqlalchemy/orm/session.py", line 467, in commit
    self._prepare_impl()
  File "/Users/gilberto.diaz/.local/share/virtualenvs/microblog-clBJ8VCo/lib/python3.6/site-packages/sqlalchemy/orm/session.py", line 447, in _prepare_impl
    self.session.flush()
  File "/Users/gilberto.diaz/.local/share/virtualenvs/microblog-clBJ8VCo/lib/python3.6/site-packages/sqlalchemy/orm/session.py", line 2254, in flush
    self._flush(objects)
  File "/Users/gilberto.diaz/.local/share/virtualenvs/microblog-clBJ8VCo/lib/python3.6/site-packages/sqlalchemy/orm/session.py", line 2380, in _flush
    transaction.rollback(_capture_exception=True)
  File "/Users/gilberto.diaz/.local/share/virtualenvs/microblog-clBJ8VCo/lib/python3.6/site-packages/sqlalchemy/util/langhelpers.py", line 66, in __exit__
    compat.reraise(exc_type, exc_value, exc_tb)
  File "/Users/gilberto.diaz/.local/share/virtualenvs/microblog-clBJ8VCo/lib/python3.6/site-packages/sqlalchemy/util/compat.py", line 187, in reraise
    raise value
  File "/Users/gilberto.diaz/.local/share/virtualenvs/microblog-clBJ8VCo/lib/python3.6/site-packages/sqlalchemy/orm/session.py", line 2344, in _flush
    flush_context.execute()
  File "/Users/gilberto.diaz/.local/share/virtualenvs/microblog-clBJ8VCo/lib/python3.6/site-packages/sqlalchemy/orm/unitofwork.py", line 391, in execute
    rec.execute(self)
  File "/Users/gilberto.diaz/.local/share/virtualenvs/microblog-clBJ8VCo/lib/python3.6/site-packages/sqlalchemy/orm/unitofwork.py", line 556, in execute
    uow
  File "/Users/gilberto.diaz/.local/share/virtualenvs/microblog-clBJ8VCo/lib/python3.6/site-packages/sqlalchemy/orm/persistence.py", line 177, in save_obj
    mapper, table, update)
  File "/Users/gilberto.diaz/.local/share/virtualenvs/microblog-clBJ8VCo/lib/python3.6/site-packages/sqlalchemy/orm/persistence.py", line 768, in _emit_update_statements
    execute(statement, multiparams)
  File "/Users/gilberto.diaz/.local/share/virtualenvs/microblog-clBJ8VCo/lib/python3.6/site-packages/sqlalchemy/engine/base.py", line 948, in execute
    return meth(self, multiparams, params)
  File "/Users/gilberto.diaz/.local/share/virtualenvs/microblog-clBJ8VCo/lib/python3.6/site-packages/sqlalchemy/sql/elements.py", line 269, in _execute_on_connection
    return connection._execute_clauseelement(self, multiparams, params)
  File "/Users/gilberto.diaz/.local/share/virtualenvs/microblog-clBJ8VCo/lib/python3.6/site-packages/sqlalchemy/engine/base.py", line 1060, in _execute_clauseelement
    compiled_sql, distilled_params
  File "/Users/gilberto.diaz/.local/share/virtualenvs/microblog-clBJ8VCo/lib/python3.6/site-packages/sqlalchemy/engine/base.py", line 1200, in _execute_context
    context)
  File "/Users/gilberto.diaz/.local/share/virtualenvs/microblog-clBJ8VCo/lib/python3.6/site-packages/sqlalchemy/engine/base.py", line 1413, in _handle_dbapi_exception
    exc_info
  File "/Users/gilberto.diaz/.local/share/virtualenvs/microblog-clBJ8VCo/lib/python3.6/site-packages/sqlalchemy/util/compat.py", line 203, in raise_from_cause
    reraise(type(exception), exception, tb=exc_tb, cause=cause)
  File "/Users/gilberto.diaz/.local/share/virtualenvs/microblog-clBJ8VCo/lib/python3.6/site-packages/sqlalchemy/util/compat.py", line 186, in reraise
    raise value.with_traceback(tb)
  File "/Users/gilberto.diaz/.local/share/virtualenvs/microblog-clBJ8VCo/lib/python3.6/site-packages/sqlalchemy/engine/base.py", line 1193, in _execute_context
    context)
  File "/Users/gilberto.diaz/.local/share/virtualenvs/microblog-clBJ8VCo/lib/python3.6/site-packages/sqlalchemy/engine/default.py", line 508, in do_execute
    cursor.execute(statement, parameters)
sqlalchemy.exc.IntegrityError: (sqlite3.IntegrityError) UNIQUE constraint failed: user.username [SQL: 'UPDATE user SET username=?, about_me=? WHERE user.id = ?'] [parameters: ('sdiaz', "I'm a data scientist and software developer that loves to extract knowledge from data.", 1)] (Background on this error at: http://sqlalche.me/e/gkpj)
2018-06-24 12:37:30,584 INFO: Microblog startup [in /Users/gilberto.diaz/workspace/microblog/src/__init__.py:44]
2018-06-24 15:39:18,813 INFO: Microblog startup [in /Users/gilberto.diaz/workspace/microblog/src/__init__.py:44]
2018-06-24 15:39:38,230 INFO: Microblog startup [in /Users/gilberto.diaz/workspace/microblog/src/__init__.py:44]
2018-06-24 15:39:47,223 INFO: Microblog startup [in /Users/gilberto.diaz/workspace/microblog/src/__init__.py:44]
2018-06-24 15:40:04,563 INFO: Microblog startup [in /Users/gilberto.diaz/workspace/microblog/src/__init__.py:44]
2018-06-24 16:14:20,693 INFO: Microblog startup [in /Users/gilberto.diaz/workspace/microblog/src/__init__.py:44]
2018-06-24 16:16:50,163 INFO: Microblog startup [in /Users/gilberto.diaz/workspace/microblog/src/__init__.py:44]
2018-06-24 16:23:13,380 INFO: Microblog startup [in /Users/gilberto.diaz/workspace/microblog/src/__init__.py:44]
2018-06-24 16:37:51,036 INFO: Microblog startup [in /Users/gilberto.diaz/workspace/microblog/src/__init__.py:44]
2018-06-24 16:39:43,702 INFO: Microblog startup [in /Users/gilberto.diaz/workspace/microblog/src/__init__.py:44]
2018-06-24 16:43:05,427 INFO: Microblog startup [in /Users/gilberto.diaz/workspace/microblog/src/__init__.py:44]
2018-06-24 17:14:52,183 INFO: Microblog startup [in /Users/gilberto.diaz/workspace/microblog/src/__init__.py:44]
2018-06-24 17:14:56,183 INFO: Microblog startup [in /Users/gilberto.diaz/workspace/microblog/src/__init__.py:44]
2018-06-24 17:15:24,266 INFO: Microblog startup [in /Users/gilberto.diaz/workspace/microblog/src/__init__.py:44]
2018-06-24 17:24:30,343 INFO: Microblog startup [in /Users/gilberto.diaz/workspace/microblog/src/__init__.py:44]
2018-06-24 17:25:15,841 INFO: Microblog startup [in /Users/gilberto.diaz/workspace/microblog/src/__init__.py:44]
2018-06-24 17:26:24,174 INFO: Microblog startup [in /Users/gilberto.diaz/workspace/microblog/src/__init__.py:44]
2018-06-24 17:27:07,499 INFO: Microblog startup [in /Users/gilberto.diaz/workspace/microblog/src/__init__.py:44]
2018-06-24 17:27:35,793 INFO: Microblog startup [in /Users/gilberto.diaz/workspace/microblog/src/__init__.py:44]
2018-06-24 17:28:14,038 INFO: Microblog startup [in /Users/gilberto.diaz/workspace/microblog/src/__init__.py:44]
2018-06-24 17:28:47,525 INFO: Microblog startup [in /Users/gilberto.diaz/workspace/microblog/src/__init__.py:44]
2018-06-24 17:44:08,381 INFO: Microblog startup [in /Users/gilberto.diaz/workspace/microblog/src/__init__.py:44]
2018-06-24 17:45:09,329 INFO: Microblog startup [in /Users/gilberto.diaz/workspace/microblog/src/__init__.py:44]
2018-06-24 17:47:07,938 INFO: Microblog startup [in /Users/gilberto.diaz/workspace/microblog/src/__init__.py:44]
2018-06-24 18:18:28,504 INFO: Microblog startup [in /Users/gilberto.diaz/workspace/microblog/src/__init__.py:44]
